Workbook

Sheet Dashborad
B1: اداره الاستحقاقات
A2: لوحة متابعة الإجازات الدراسية
A3: اخر تحديث | B3: =TODAY() -> 46259
A4: اجمالي الموظفين | B4: =COUNTA('الاجازات الدراسيه'!B3:B1035) -> 52
A5: يصرف المرتب | B5: =COUNTIF('الاجازات الدراسيه'!N3:N1035,"يصرف المرتب") -> 49
A6: يوقف المرتب | B6: =COUNTIF('الاجازات الدراسيه'!N3:N1035,"يوقف المرتب") -> 3
A7: بدون مرتب | B7: =COUNTIF('الاجازات الدراسيه'!N3:N1035,"بدون مرتب") -> 0
A8: باقي أقل من 30 يوم | B8: =COUNTIFS('الاجازات الدراسيه'!L3:L1035,">0",'الاجازات الدراسيه'!L3:L1035,"<=30") -> 1
A9: باقي من 31 إلى 90 يوم | B9: =COUNTIFS('الاجازات الدراسيه'!L3:L1035,">30",'الاجازات الدراسيه'!L3:L1035,"<=90") -> 2

Sheet الاجازات الدراسيه
A2: م | B2: كود الموظف | C2: الاسم | D2: الدرجة | E2: نوع الإجازة | F2: رقم الأمر التنفيذي | G2: تاريخ الأمر التنفيذي | H2: تاريخ الأمر التنفيذي2 | I2: بداية الإجازة | J2: نهاية الإجازة | K2: انتهاء 5 سنوات | L2: الأيام المتبقية | M2: حالة الإجازة | N2: حالة المرتب | O2: عاد للعمل؟ | P2: سبب انتهاء الخدمة | Q2: تم عمل مطالبة؟
A3: 1 | B3: 37099 | C3: حسام حسن عبد المنعم السيد | D3: مدرس مساعد | E3: يصرف بمرتب | F3: 7920 | G3: 45923 | H3: اجازه دراسيه | I3: 45967 | J3: 46331 | K3: =EDATE(I3,60) -> 47793 | L3: =IF(K3="","",MAX(0,K3-TODAY())) -> 1534 | M3: =IF(J2="",K12,IF(J2>=TODAY(),"سارية","منتهية")) -> سارية | N3: =IF(E3="بدون مرتب","بدون مرتب",IF(K3<=TODAY(),"يوقف المرتب","يصرف المرتب")) -> يصرف المرتب
A4: 2 | B4: 35687 | C4: اسامه محمد فكرى حسن | D4: استاذ مساعد | E4: يصرف بمرتب | F4: 8828 | G4: 45574 | H4: اجازه دراسيه | I4: 45526 | J4: 46142 | K4: =EDATE(I4,60) -> 47352 | L4: =IF(K4="","",MAX(0,K4-TODAY())) -> 1093 | M4: =IF(J3="",#REF!,IF(J3>=TODAY(),"سارية","منتهية")) -> سارية | N4: =IF(E4="بدون مرتب","بدون مرتب",IF(K4<=TODAY(),"يوقف المرتب","يصرف المرتب")) -> يصرف المرتب
A5: 3 | B5: 37069 | C5: جون منير عدلي جرجس | D5: معيد | E5: يصرف بمرتب | F5: 4674 | H5: اجازه دراسيه | I5: 45153 | J5: 46143 | K5: =EDATE(I5,60) -> 46980 | L5: =IF(K5="","",MAX(0,K5-TODAY())) -> 721 | M5: =IF(J4="",#REF!,IF(J4>=TODAY(),"سارية","منتهية")) -> منتهية | N5: =IF(E5="بدون مرتب","بدون مرتب",IF(K5<=TODAY(),"يوقف المرتب","يصرف المرتب")) -> يصرف المرتب
A6: 4 | B6: 35727 | C6: ابراهيم فكرى جابر محمد | D6: مدرس | E6: يصرف بمرتب | F6: 10182 | G6: 45942 | H6: مهمه علميه | I6: 45927 | J6: 46291 | K6: =EDATE(I6,60) -> 47753 | L6: =IF(K6="","",MAX(0,K6-TODAY())) -> 1494 | M6: =IF(J5="",K13,IF(J5>=TODAY(),"سارية","منتهية")) -> منتهية | N6: =IF(E6="بدون مرتب","بدون مرتب",IF(K6<=TODAY(),"يوقف المرتب","يصرف المرتب")) -> يصرف المرتب
A7: 5 | B7: 37191 | C7: عمرو عماد سعيد محمد | D7: مدرس مساعد | E7: يصرف بمرتب | F7: 10258 | G7: 45670 | H7: اجازه دراسيه | I7: 45874 | J7: 46238 | K7: =EDATE(I7,60) -> 47700 | L7: =IF(K7="","",MAX(0,K7-TODAY())) -> 1441 | M7: =IF(J6="",K14,IF(J6>=TODAY(),"سارية","منتهية")) -> سارية | N7: =IF(E7="بدون مرتب","بدون مرتب",IF(K7<=TODAY(),"يوقف المرتب","يصرف المرتب")) -> يصرف المرتب
A8: 6 | B8: 37346 | C8: احمد عبد الستار سيد الجازوي | D8: مدرس مساعد | E8: يصرف بمرتب | F8: 10194 | G8: 45942 | H8: اجازه دراسيه | I8: 45758 | J8: 46122 | K8: =EDATE(I8,60) -> 47584 | L8: =IF(K8="","",MAX(0,K8-TODAY())) -> 1325 | M8: =IF(J7="",K15,IF(J7>=TODAY(),"سارية","منتهية")) -> منتهية | N8: =IF(E8="بدون مرتب","بدون مرتب",IF(K8<=TODAY(),"يوقف المرتب","يصرف المرتب")) -> يصرف المرتب
A9: 7 | B9: 37028 | C9: احمد فتحي حسين فتحي ابو الحمايد | D9: مدرس مساعد | E9: يصرف بمرتب | F9: 1365 | G9: 46065 | H9: اجازه دراسيه | I9: 44790 | J9: 46250 | K9: =EDATE(I9,60) -> 46616 | L9: =IF(K9="","",MAX(0,K9-TODAY())) -> 357 | M9: =IF(J8="",K16,IF(J8>=TODAY(),"سارية","منتهية")) -> منتهية | N9: =IF(E9="بدون مرتب","بدون مرتب",IF(K9<=TODAY(),"يوقف المرتب","يصرف المرتب")) -> يصرف المرتب
A10: 8 | B10: 37228 | C10: مازن خالد انور احمد قنديل | D10: مدرس مساعد | E10: يصرف بمرتب | F10: 1379 | G10: 46068 | H10: اجازه دراسيه | I10: 45304 | J10: 46399 | K10: =EDATE(I10,60) -> 47131 | L10: =IF(K10="","",MAX(0,K10-TODAY())) -> 872 | M10: =IF(J9="",K17,IF(J9>=TODAY(),"سارية","منتهية")) -> منتهية | N10: =IF(E10="بدون مرتب","بدون مرتب",IF(K10<=TODAY(),"يوقف المرتب","يصرف المرتب")) -> يصرف المرتب
A11: 9 | B11: 37085 | C11: عبد الله صلاح محمد اب يوسف | D11: مدرس مساعد | E11: يصرف بمرتب | F11: 11766 | G11: 45985 | H11: اجازه دراسيه | I11: 44805 | J11: 46263 | K11: =EDATE(I11,60) -> 46631 | L11: =IF(K11="","",MAX(0,K11-TODAY())) -> 372 | M11: =IF(J10="",K20,IF(J10>=TODAY(),"سارية","منتهية")) -> سارية | N11: =IF(E11="بدون مرتب","بدون مرتب",IF(K11<=TODAY(),"يوقف المرتب","يصرف المرتب")) -> يصرف المرتب
A12: 10 | B12: 35945 | C12: احمد خالد محمد صلاح الدين حسنين | D12: مدرس مساعد | E12: يصرف بمرتب | F12: 11261 | G12: 45973 | H12: اجازه دراسيه | I12: 45160 | J12: 46255 | K12: =EDATE(I12,60) -> 46987 | L12: =IF(K12="","",MAX(0,K12-TODAY())) -> 728 | M12: =IF(J11="",#REF!,IF(J11>=TODAY(),"سارية","منتهية")) -> سارية | N12: =IF(E12="بدون مرتب","بدون مرتب",IF(K12<=TODAY(),"يوقف المرتب","يصرف المرتب")) -> يصرف المرتب
A13: 11 | B13: 37346 | C13: هشام محمد طه السيد محمد | D13: مدرس مساعد | E13: يصرف بمرتب | F13: 634 | G13: 45951 | H13: اجازه دراسيه | I13: 45026 | J13: 46017 | K13: =EDATE(I13,60) -> 46853 | L13: =IF(K13="","",MAX(0,K13-TODAY())) -> 594 | M13: =IF(J12="",#REF!,IF(J12>=TODAY(),"سارية","منتهية")) -> منتهية | N13: =IF(E13="بدون مرتب","بدون مرتب",IF(K13<=TODAY(),"يوقف المرتب","يصرف المرتب")) -> يصرف المرتب
A14: 12 | B14: 37179 | C14: ندي نادر عثمان علد الخالق السعدني | D14: معيد | E14: يصرف بمرتب | F14: 2810 | G14: 45755 | H14: اجازه دراسيه | I14: 45804 | J14: 46199 | K14: =EDATE(I14,60) -> 47630 | L14: =IF(K14="","",MAX(0,K14-TODAY())) -> 1371 | M14: =IF(J13="",K21,IF(J13>=TODAY(),"سارية","منتهية")) -> منتهية | N14: =IF(E14="بدون مرتب","بدون مرتب",IF(K14<=TODAY(),"يوقف المرتب","يصرف المرتب")) -> يصرف المرتب
A15: 13 | B15: 37140 | C15: اسامه نجيب احمد علوان ابراهيم | D15: مدرس مساعد | E15: يصرف بمرتب | F15: 9571 | G15: 45925 | H15: اجازه دراسيه | I15: 45521 | J15: 46250 | K15: =EDATE(I15,60) -> 47347 | L15: =IF(K15="","",MAX(0,K15-TODAY())) -> 1088 | M15: =IF(J14="",K22,IF(J14>=TODAY(),"سارية","منتهية")) -> منتهية | N15: =IF(E15="بدون مرتب","بدون مرتب",IF(K15<=TODAY(),"يوقف المرتب","يصرف المرتب")) -> يصرف المرتب
A16: 14 | B16: 37053 | C16: وليد السيد محمد محمد الزيتي | D16: مدرس مساعد | E16: يصرف بمرتب | F16: 9186 | G16: 45914 | H16: اجازه دراسيه | I16: 45513 | J16: 46242 | K16: =EDATE(I16,60) -> 47339 | L16: =IF(K16="","",MAX(0,K16-TODAY())) -> 1080 | M16: =IF(J15="",K62,IF(J15>=TODAY(),"سارية","منتهية")) -> منتهية | N16: =IF(E16="بدون مرتب","بدون مرتب",IF(K16<=TODAY(),"يوقف المرتب","يصرف المرتب")) -> يصرف المرتب
A17: 15 | B17: 37172 | C17: كريم محمد محمد المليجي | D17: معيد | E17: يصرف بمرتب | F17: 9187 | G17: 45914 | H17: اجازه دراسيه | I17: 45161 | J17: 46256 | K17: =EDATE(I17,60) -> 46988 | L17: =IF(K17="","",MAX(0,K17-TODAY())) -> 729 | M17: =IF(J16="",K63,IF(J16>=TODAY(),"سارية","منتهية")) -> منتهية | N17: =IF(E17="بدون مرتب","بدون مرتب",IF(K17<=TODAY(),"يوقف المرتب","يصرف المرتب")) -> يصرف المرتب
A18: 16 | B18: 37003 | C18: محمد مصطفي عبد الحميد رمضان | D18: مدرس مساعد | E18: يصرف بمرتب | F18: 8871 | G18: 45908 | H18: اجازه دراسيه | I18: 44929 | J18: 46024 | K18: =EDATE(I18,60) -> 46755 | L18: =IF(K18="","",MAX(0,K18-TODAY())) -> 496 | M18: =IF(J17="",#REF!,IF(J17>=TODAY(),"سارية","منتهية")) -> منتهية | N18: =IF(E18="بدون مرتب","بدون مرتب",IF(K18<=TODAY(),"يوقف المرتب","يصرف المرتب")) -> يصرف المرتب
A19: 17 | B19: 37125 | C19: ماركو عدلي غالي سيف | D19: معيد | E19: يصرف بمرتب | F19: 8868 | G19: 45908 | H19: اجازه دراسيه | I19: 44740 | J19: 46200 | K19: =EDATE(I19,60) -> 46566 | L19: =IF(K19="","",MAX(0,K19-TODAY())) -> 307 | M19: =IF(J18="",K64,IF(J18>=TODAY(),"سارية","منتهية")) -> منتهية | N19: =IF(E19="بدون مرتب","بدون مرتب",IF(K19<=TODAY(),"يوقف المرتب","يصرف المرتب")) -> يصرف المرتب
A20: 18 | B20: 8869 | C20: رضوى يسري احمد عبد الحليم | D20: معيده | E20: يصرف بمرتب | F20: 8869 | G20: 45908 | H20: اجازه دراسيه | I20: 45422 | J20: 46151 | K20: =EDATE(I20,60) -> 47248 | L20: =IF(K20="","",MAX(0,K20-TODAY())) -> 989 | M20: =IF(J19="",K65,IF(J19>=TODAY(),"سارية","منتهية")) -> منتهية | N20: =IF(E20="بدون مرتب","بدون مرتب",IF(K20<=TODAY(),"يوقف المرتب","يصرف المرتب")) -> يصرف المرتب
A21: 19 | B21: 8715 | C21: اسلام محمد منير محمد | D21: مدرس مساعد | E21: يصرف بمرتب | F21: 8715 | G21: 45902 | H21: اجازه دراسيه | I21: 44203 | J21: 46028 | K21: =EDATE(I21,60) -> 46029 | L21: =IF(K21="","",MAX(0,K21-TODAY())) -> 0 | M21: =IF(J20="",K66,IF(J20>=TODAY(),"سارية","منتهية")) -> منتهية | N21: =IF(E21="بدون مرتب","بدون مرتب",IF(K21<=TODAY(),"يوقف المرتب","يصرف المرتب")) -> يوقف المرتب
A22: 20 | B22: 8726 | C22: احمد طارق ابو الفتوح محمد المرسي دهشان | D22: معيد | E22: يصرف بمرتب | F22: 8716 | G22: 45902 | H22: اجازه دراسيه | I22: 45206 | J22: 45936 | K22: =EDATE(I22,60) -> 47033 | L22: =IF(K22="","",MAX(0,K22-TODAY())) -> 774 | M22: =IF(J21="",K67,IF(J21>=TODAY(),"سارية","منتهية")) -> منتهية | N22: =IF(E22="بدون مرتب","بدون مرتب",IF(K22<=TODAY(),"يوقف المرتب","يصرف المرتب")) -> يصرف المرتب
A23: 21 | B23: 37118 | C23: هشام صلاح عبد الفتاح موسي | D23: مدرس مساعد | E23: يصرف بمرتب | F23: 13114 | G23: 46022 | H23: اجازه دراسيه | I23: 45717 | J23: 45902 | K23: =EDATE(I23,60) -> 47543 | L23: =IF(K23="","",MAX(0,K23-TODAY())) -> 1284 | M23: =IF(J22="",K68,IF(J22>=TODAY(),"سارية","منتهية")) -> منتهية | N23: =IF(E23="بدون مرتب","بدون مرتب",IF(K23<=TODAY(),"يوقف المرتب","يصرف المرتب")) -> يصرف المرتب
A24: 22 | B24: 35954 | C24: حسين خالد حسين عبد العزيز زهران | D24: مدرس مساعد | E24: يصرف بمرتب | F24: 957 | G24: 46040 | H24: اجازه دراسيه | I24: 44469 | J24: 45962 | K24: =EDATE(I24,60) -> 46295 | L24: =IF(K24="","",MAX(0,K24-TODAY())) -> 36 | M24: =IF(J23="",K69,IF(J23>=TODAY(),"سارية","منتهية")) -> منتهية | N24: =IF(E24="بدون مرتب","بدون مرتب",IF(K24<=TODAY(),"يوقف المرتب","يصرف المرتب")) -> يصرف المرتب
A25: 23 | B25: 37252 | C25: منى محمد كامل خضري | D25: مدرس مساعد | E25: يصرف بمرتب | F25: 45922 | H25: اجازه دراسيه | I25: 45880 | J25: 46244 | K25: =EDATE(I25,60) -> 47706 | L25: =IF(K25="","",MAX(0,K25-TODAY())) -> 1447 | M25: =IF(J24="",K70,IF(J24>=TODAY(),"سارية","منتهية")) -> منتهية | N25: =IF(E25="بدون مرتب","بدون مرتب",IF(K25<=TODAY(),"يوقف المرتب","يصرف المرتب")) -> يصرف المرتب
A26: 24 | B26: 35673 | C26: محمد احمد السيد احمد زايد | D26: مدرس | E26: يصرف بمرتب | F26: 1063 | G26: 46055 | H26: اجازه دراسيه | I26: 45310 | J26: 46042 | K26: =EDATE(I26,60) -> 47137 | L26: =IF(K26="","",MAX(0,K26-TODAY())) -> 878 | M26: =IF(J25="",K71,IF(J25>=TODAY(),"سارية","منتهية")) -> منتهية | N26: =IF(E26="بدون مرتب","بدون مرتب",IF(K26<=TODAY(),"يوقف المرتب","يصرف المرتب")) -> يصرف المرتب
A27: 25 | B27: 37028 | C27: احمد فتحى حسين فتحى | D27: مدرس مساعد | E27: يصرف بمرتب | F27: 10146 | G27: 45938 | H27: اجازه دراسيه | I27: 44790 | J27: 45154 | K27: =EDATE(I27,60) -> 46616 | L27: =IF(K27="","",MAX(0,K27-TODAY())) -> 357 | M27: =IF(J26="",K72,IF(J26>=TODAY(),"سارية","منتهية")) -> منتهية | N27: =IF(E27="بدون مرتب","بدون مرتب",IF(K27<=TODAY(),"يوقف المرتب","يصرف المرتب")) -> يصرف المرتب
A28: 26 | B28: 37014 | C28: محمد صلاح محمد العراقى | D28: مدرس مساعد | E28: يصرف بمرتب | G28: 46036 | H28: اجازه دراسيه | I28: 45170 | J28: 45169 | K28: =EDATE(I28,60) -> 46997 | L28: =IF(K28="","",MAX(0,K28-TODAY())) -> 738 | M28: =IF(J27="",K73,IF(J27>=TODAY(),"سارية","منتهية")) -> منتهية | N28: =IF(E28="بدون مرتب","بدون مرتب",IF(K28<=TODAY(),"يوقف المرتب","يصرف المرتب")) -> يصرف المرتب
A29: 27 | B29: 36994 | C29: محمد صلاح محمد العراقى | D29: معيد | E29: يصرف بمرتب | F29: 828 | G29: 46043 | H29: اجازه دراسيه | I29: 44354 | J29: 46179 | K29: =EDATE(I29,60) -> 46180 | L29: =IF(K29="","",MAX(0,K29-TODAY())) -> 0 | M29: =IF(J28="",K74,IF(J28>=TODAY(),"سارية","منتهية")) -> منتهية | N29: =IF(E29="بدون مرتب","بدون مرتب",IF(K29<=TODAY(),"يوقف المرتب","يصرف المرتب")) -> يوقف المرتب
A30: 28 | B30: 37075 | C30: بيشوى ميلاد حلمى زكى | D30: مدرس مساعد | E30: يصرف بمرتب | F30: 1159 | G30: 46057 | H30: اجازه دراسيه | I30: 45258 | J30: 46353 | K30: =EDATE(I30,60) -> 47085 | L30: =IF(K30="","",MAX(0,K30-TODAY())) -> 826 | M30: =IF(J29="",K75,IF(J29>=TODAY(),"سارية","منتهية")) -> منتهية | N30: =IF(E30="بدون مرتب","بدون مرتب",IF(K30<=TODAY(),"يوقف المرتب","يصرف المرتب")) -> يصرف المرتب
A31: 29 | B31: 37081 | C31: مصطفى محمد هشام كامل طوبار | D31: مدرس مساعد | E31: يصرف بمرتب | F31: 10784 | G31: 45956 | H31: اجازه دراسيه | I31: 45154 | J31: 46250 | K31: =EDATE(I31,60) -> 46981 | L31: =IF(K31="","",MAX(0,K31-TODAY())) -> 722 | M31: =IF(J30="",K76,IF(J30>=TODAY(),"سارية","منتهية")) -> سارية | N31: =IF(E31="بدون مرتب","بدون مرتب",IF(K31<=TODAY(),"يوقف المرتب","يصرف المرتب")) -> يصرف المرتب
A32: 30 | B32: 37020 | C32: احمد صلاح الدين حسن جمال الدين | D32: مدرس مساعد | E32: يصرف بمرتب | F32: 10482 | G32: 45949 | H32: اجازه دراسيه | I32: 44809 | J32: 46270 | K32: =EDATE(I32,60) -> 46635 | L32: =IF(K32="","",MAX(0,K32-TODAY())) -> 376 | M32: =IF(J31="",K77,IF(J31>=TODAY(),"سارية","منتهية")) -> منتهية | N32: =IF(E32="بدون مرتب","بدون مرتب",IF(K32<=TODAY(),"يوقف المرتب","يصرف المرتب")) -> يصرف المرتب
A33: 31 | B33: 37047 | C33: هشام محمد طه السيد | D33: مدرس مساعد | E33: يصرف بمرتب | F33: 1071 | G33: 46055 | H33: اجازه دراسيه | I33: 44922 | J33: 46382 | K33: =EDATE(I33,60) -> 46748 | L33: =IF(K33="","",MAX(0,K33-TODAY())) -> 489 | M33: =IF(J32="",K78,IF(J32>=TODAY(),"سارية","منتهية")) -> سارية | N33: =IF(E33="بدون مرتب","بدون مرتب",IF(K33<=TODAY(),"يوقف المرتب","يصرف المرتب")) -> يصرف المرتب
A34: 32 | B34: 37088 | C34: محمد عبد الحكيم محمد كيلانى | D34: معيد | E34: يصرف بمرتب | F34: 10481 | G34: 45949 | H34: اجازه دراسيه | I34: 45141 | J34: 46236 | K34: =EDATE(I34,60) -> 46968 | L34: =IF(K34="","",MAX(0,K34-TODAY())) -> 709 | M34: =IF(J33="",K79,IF(J33>=TODAY(),"سارية","منتهية")) -> سارية | N34: =IF(E34="بدون مرتب","بدون مرتب",IF(K34<=TODAY(),"يوقف المرتب","يصرف المرتب")) -> يصرف المرتب
A35: 33 | B35: 37185 | C35: عمر حسن عبد السميع دسوقى | D35: مدرس مساعد | E35: يصرف بمرتب | F35: 721 | G35: 46042 | H35: اجازه دراسيه | I35: 20/8//2025 | J35: 46237 | K35: =EDATE(I34,60) -> 46968 | L35: =IF(K35="","",MAX(0,K35-TODAY())) -> 709 | M35: =IF(J33="",K79,IF(J33>=TODAY(),"سارية","منتهية")) -> سارية | N35: =IF(E34="بدون مرتب","بدون مرتب",IF(K35<=TODAY(),"يوقف المرتب","يصرف المرتب")) -> يصرف المرتب
A36: 34 | B36: 370767 | C36: محمد حسام بدر الدين ابراهيم منصور | D36: معيد | E36: يصرف بمرتب | F36: 648 | G36: 45852 | H36: اجازه دراسيه | I36: 44716 | J36: 46177 | K36: =EDATE(I36,60) -> 46542 | L36: =IF(K36="","",MAX(0,K36-TODAY())) -> 283 | M36: =IF(J35="",K81,IF(J35>=TODAY(),"سارية","منتهية")) -> منتهية | N36: =IF(E36="بدون مرتب","بدون مرتب",IF(K36<=TODAY(),"يوقف المرتب","يصرف المرتب")) -> يصرف المرتب
A37: 35 | B37: 37117 | C37: محمد المتولي محمد السيد سيد احمد | D37: مدرس مساعد | E37: يصرف بمرتب | F37: 6771 | G37: 45858 | H37: اجازه دراسيه | I37: 44682 | J37: 46142 | K37: =EDATE(I37,60) -> 46508 | L37: =IF(K37="","",MAX(0,K37-TODAY())) -> 249 | M37: =IF(J36="",K82,IF(J36>=TODAY(),"سارية","منتهية")) -> منتهية | N37: =IF(E37="بدون مرتب","بدون مرتب",IF(K37<=TODAY(),"يوقف المرتب","يصرف المرتب")) -> يصرف المرتب
A38: 36 | B38: 37150 | C38: محمد اسامه رمضان علي سليم | D38: معيد | E38: يصرف بمرتب | F38: 7925 | G38: 45888 | H38: اجازه دراسيه | I38: 45084 | J38: 46179 | K38: =EDATE(I38,60) -> 46911 | L38: =IF(K38="","",MAX(0,K38-TODAY())) -> 652 | M38: =IF(J37="",K83,IF(J37>=TODAY(),"سارية","منتهية")) -> منتهية | N38: =IF(E38="بدون مرتب","بدون مرتب",IF(K38<=TODAY(),"يوقف المرتب","يصرف المرتب")) -> يصرف المرتب
A39: 37 | B39: 37138 | C39: محمد شاكر احمد البهي ابراهيم | D39: معيد | E39: يصرف بمرتب | F39: 8122 | G39: 45890 | H39: اجازه دراسيه | I39: 44672 | J39: 46022 | K39: =EDATE(I39,60) -> 46498 | L39: =IF(K39="","",MAX(0,K39-TODAY())) -> 239 | M39: =IF(J38="",K84,IF(J38>=TODAY(),"سارية","منتهية")) -> منتهية | N39: =IF(E39="بدون مرتب","بدون مرتب",IF(K39<=TODAY(),"يوقف المرتب","يصرف المرتب")) -> يصرف المرتب
A40: 38 | B40: 37216 | C40: احمد يس عبد القادر عبد الحميد | D40: معيد | E40: يصرف بمرتب | F40: 10485 | G40: 45949 | H40: اجازه دراسيه | I40: 45518 | J40: 46247 | K40: =EDATE(I40,60) -> 47344 | L40: =IF(K40="","",MAX(0,K40-TODAY())) -> 1085 | M40: =IF(J39="",K85,IF(J39>=TODAY(),"سارية","منتهية")) -> منتهية | N40: =IF(E40="بدون مرتب","بدون مرتب",IF(K40<=TODAY(),"يوقف المرتب","يصرف المرتب")) -> يصرف المرتب
A41: 39 | B41: 37108 | C41: هيا هشام السعيد سلمان حسن | D41: مدرس مساعد | E41: يصرف بمرتب | F41: 558 | G41: 45676 | H41: اجازه دراسيه | I41: 45641 | J41: 46006 | K41: =EDATE(I41,60) -> 47467 | L41: =IF(K41="","",MAX(0,K41-TODAY())) -> 1208 | M41: =IF(J40="",K86,IF(J40>=TODAY(),"سارية","منتهية")) -> منتهية | N41: =IF(E41="بدون مرتب","بدون مرتب",IF(K41<=TODAY(),"يوقف المرتب","يصرف المرتب")) -> يصرف المرتب
...

Sheet الاعدادات
